Traceback (most recent call last):
  File "C:\Users\yuuki\AppData\Local\Programs\Python\Python313\Lib\site-packages\urllib3\connectionpool.py", line 464, in _make_request
    self._validate_conn(conn)
  File "C:\Users\yuuki\AppData\Local\Programs\Python\Python313\Lib\site-packages\urllib3\connectionpool.py", line 1093, in _validate_conn
    conn.connect()
  File "C:\Users\yuuki\AppData\Local\Programs\Python\Python313\Lib\site-packages\urllib3\connection.py", line 741, in connect
    sock_and_verified = _ssl_wrap_socket_and_match_hostname(
  File "C:\Users\yuuki\AppData\Local\Programs\Python\Python313\Lib\site-packages\urllib3\connection.py", line 920, in _ssl_wrap_socket_and_match_hostname
    ssl_sock = ssl_wrap_socket(
  File "C:\Users\yuuki\AppData\Local\Programs\Python\Python313\Lib\site-packages\urllib3\util\ssl_.py", line 460, in ssl_wrap_socket
    ssl_sock = _ssl_wrap_socket_impl(sock, context, tls_in_tls, server_hostname)
  File "C:\Users\yuuki\AppData\Local\Programs\Python\Python313\Lib\site-packages\urllib3\util\ssl_.py", line 504, in _ssl_wrap_socket_impl
    return ssl_context.wrap_socket(sock, server_hostname=server_hostname)
  File "C:\Users\yuuki\AppData\Local\Programs\Python\Python313\Lib\ssl.py", line 455, in wrap_socket
    return self.sslsocket_class._create(
  File "C:\Users\yuuki\AppData\Local\Programs\Python\Python313\Lib\ssl.py", line 1076, in _create
    self.do_handshake()
  File "C:\Users\yuuki\AppData\Local\Programs\Python\Python313\Lib\ssl.py", line 1372, in do_handshake
    self._sslobj.do_handshake()
ssl.SSLError: [SSL: SSLV3_ALERT_ILLEGAL_PARAMETER] sslv3 alert illegal parameter (_ssl.c:1020)

During handling of the above exception, another exception occurred:

Traceback (most recent call last):
  File "C:\Users\yuuki\AppData\Local\Programs\Python\Python313\Lib\site-packages\urllib3\connectionpool.py", line 787, in urlopen
    response = self._make_request(
  File "C:\Users\yuuki\AppData\Local\Programs\Python\Python313\Lib\site-packages\urllib3\connectionpool.py", line 488, in _make_request
    raise new_e
urllib3.exceptions.SSLError: [SSL: SSLV3_ALERT_ILLEGAL_PARAMETER] sslv3 alert illegal parameter (_ssl.c:1020)

The above exception was the direct cause of the following exception:

Traceback (most recent call last):
  File "C:\Users\yuuki\AppData\Local\Programs\Python\Python313\Lib\site-packages\requests\adapters.py", line 667, in send
    resp = conn.urlopen(
  File "C:\Users\yuuki\AppData\Local\Programs\Python\Python313\Lib\site-packages\urllib3\connectionpool.py", line 841, in urlopen
    retries = retries.increment(
  File "C:\Users\yuuki\AppData\Local\Programs\Python\Python313\Lib\site-packages\urllib3\util\retry.py", line 519, in increment
    raise MaxRetryError(_pool, url, reason) from reason  # type: ignore[arg-type]
urllib3.exceptions.MaxRetryError: HTTPSConnectionPool(host='apis.data.go.kr', port=443): Max retries exceeded with url: /B552584/ArpltnInforInqireSvc/getMinuDustFrcstDspth?serviceKey=ntHgt3rvR5X6%2FZFHKiy4d1WOMFQ0bCAVYqFJTyKDGdkk1F%2BO11u7RFA0EVx%2FgLVHa8tnOjlILYfmWVR69IvNJw%3D%3D&returnType=json&numOfRows=100&pageNo=1&searchDate=2025-06-19&InformCode=PM10 (Caused by SSLError(SSLError(1, '[SSL: SSLV3_ALERT_ILLEGAL_PARAMETER] sslv3 alert illegal parameter (_ssl.c:1020)')))

During handling of the above exception, another exception occurred:

Traceback (most recent call last):
  File "C:\Users\yuuki\GitProject\Pythonstudy\1\requests로 공공데이터포털 API 호출.py", line 18, in <module>
    res = requests.get(url, verify=False)
  File "C:\Users\yuuki\AppData\Local\Programs\Python\Python313\Lib\site-packages\requests\api.py", line 73, in get
    return request("get", url, params=params, **kwargs)
  File "C:\Users\yuuki\AppData\Local\Programs\Python\Python313\Lib\site-packages\requests\api.py", line 59, in request
    return session.request(method=method, url=url, **kwargs)
  File "C:\Users\yuuki\AppData\Local\Programs\Python\Python313\Lib\site-packages\requests\sessions.py", line 589, in request
    resp = self.send(prep, **send_kwargs)
  File "C:\Users\yuuki\AppData\Local\Programs\Python\Python313\Lib\site-packages\requests\sessions.py", line 703, in send
    r = adapter.send(request, **kwargs)
  File "C:\Users\yuuki\AppData\Local\Programs\Python\Python313\Lib\site-packages\requests\adapters.py", line 698, in send
    raise SSLError(e, request=request)
requests.exceptions.SSLError: HTTPSConnectionPool(host='apis.data.go.kr', port=443): Max retries exceeded with url: /B552584/ArpltnInforInqireSvc/getMinuDustFrcstDspth?serviceKey=ntHgt3rvR5X6%2FZFHKiy4d1WOMFQ0bCAVYqFJTyKDGdkk1F%2BO11u7RFA0EVx%2FgLVHa8tnOjlILYfmWVR69IvNJw%3D%3D&returnType=json&numOfRows=100&pageNo=1&searchDate=2025-06-19&InformCode=PM10 (Caused by SSLError(SSLError(1, '[SSL: SSLV3_ALERT_ILLEGAL_PARAMETER] sslv3 alert illegal parameter (_ssl.c:1020)')))